Python 3.7.3
Welcome! The program is running on cuda. It may take a while...
I am using configuration file number 55
Epoch 1/20: train_loss: 0.6060, train_accuracy: 68.0556, val_loss: 0.7106, val_accuracy: 50.0000
Epoch 2/20: train_loss: 0.5924, train_accuracy: 68.4222, val_loss: 0.7331, val_accuracy: 50.0000
Epoch 3/20: train_loss: 0.5756, train_accuracy: 69.7889, val_loss: 0.7249, val_accuracy: 52.1000
Epoch 4/20: train_loss: 0.5728, train_accuracy: 69.7389, val_loss: 0.7084, val_accuracy: 49.9000
Epoch 5/20: train_loss: 0.6640, train_accuracy: 54.9222, val_loss: 0.6935, val_accuracy: 50.0000
Epoch 6/20: train_loss: 0.6934, train_accuracy: 50.1111, val_loss: 0.6932, val_accuracy: 50.0000
Epoch 7/20: train_loss: 0.6932, train_accuracy: 50.1222, val_loss: 0.6931, val_accuracy: 50.0000
Epoch 8/20: train_loss: 0.6933, train_accuracy: 50.0222, val_loss: 0.6931, val_accuracy: 50.0000
Epoch 9/20: train_loss: 0.6933, train_accuracy: 50.2444, val_loss: 0.6932, val_accuracy: 50.0000
Epoch 10/20: train_loss: 0.6933, train_accuracy: 49.6333, val_loss: 0.6932, val_accuracy: 50.0000
Epoch 11/20: train_loss: 0.6933, train_accuracy: 49.9667, val_loss: 0.6931, val_accuracy: 50.0000
Epoch 12/20: train_loss: 0.6935, train_accuracy: 49.7222, val_loss: 0.6932, val_accuracy: 50.0000
Epoch 13/20: train_loss: 0.6935, train_accuracy: 50.1556, val_loss: 0.6932, val_accuracy: 50.0000
Epoch 14/20: train_loss: 0.6934, train_accuracy: 49.5667, val_loss: 0.6932, val_accuracy: 50.0000
Epoch 15/20: train_loss: 0.6933, train_accuracy: 50.2778, val_loss: 0.6932, val_accuracy: 50.0000
Epoch 16/20: train_loss: 0.6934, train_accuracy: 49.5111, val_loss: 0.6931, val_accuracy: 50.0000
Epoch 17/20: train_loss: 0.6934, train_accuracy: 50.7889, val_loss: 0.6932, val_accuracy: 50.0000
Epoch 18/20: train_loss: 0.6934, train_accuracy: 50.1222, val_loss: 0.6931, val_accuracy: 50.0000
Epoch 19/20: train_loss: 0.6934, train_accuracy: 50.1889, val_loss: 0.6931, val_accuracy: 50.0000
Epoch 20/20: train_loss: 0.6934, train_accuracy: 49.5556, val_loss: 0.6932, val_accuracy: 50.0000
Traceback (most recent call last):
  File "ATML/main.py", line 114, in <module>
    torch.save(model.state_dict(), model_dir + 'model' + experiment_name + '.pt')
  File "/home/ubelix/artorg/kc12n043/miniconda3/envs/atml/lib/python3.7/site-packages/torch/serialization.py", line 224, in save
    return _with_file_like(f, "wb", lambda f: _save(obj, f, pickle_module, pickle_protocol))
  File "/home/ubelix/artorg/kc12n043/miniconda3/envs/atml/lib/python3.7/site-packages/torch/serialization.py", line 147, in _with_file_like
    f = open(f, mode)
FileNotFoundError: [Errno 2] No such file or directory: '../models/model55.pt'
