Python 3.7.3
Welcome! The program is running on cuda. It may take a while...
I am using configuration file number 7
Epoch 1/25: train_loss: 0.6931, train_accuracy: 50.2833, val_loss: 0.6932, val_accuracy: 50.0000
Epoch 2/25: train_loss: 0.6927, train_accuracy: 53.2444, val_loss: 0.6925, val_accuracy: 52.2000
Epoch 3/25: train_loss: 0.6853, train_accuracy: 58.4333, val_loss: 0.6977, val_accuracy: 48.4000
Epoch 4/25: train_loss: 0.5822, train_accuracy: 67.8278, val_loss: 0.7122, val_accuracy: 50.9000
Epoch 5/25: train_loss: 0.5378, train_accuracy: 70.4722, val_loss: 0.6203, val_accuracy: 61.3000
Epoch 6/25: train_loss: 0.4671, train_accuracy: 75.8611, val_loss: 0.5907, val_accuracy: 67.7000
Epoch 7/25: train_loss: 0.4228, train_accuracy: 77.7444, val_loss: 0.5620, val_accuracy: 67.9000
Epoch 8/25: train_loss: 0.4037, train_accuracy: 78.8611, val_loss: 0.5479, val_accuracy: 68.8000
Epoch 9/25: train_loss: 0.3839, train_accuracy: 79.8056, val_loss: 0.6221, val_accuracy: 65.2000
Epoch 10/25: train_loss: 0.3750, train_accuracy: 80.6889, val_loss: 0.5622, val_accuracy: 65.6000
Epoch 11/25: train_loss: 0.3638, train_accuracy: 81.5778, val_loss: 0.5121, val_accuracy: 70.8000
Epoch 12/25: train_loss: 0.3501, train_accuracy: 82.5278, val_loss: 0.5083, val_accuracy: 72.3000
Epoch 13/25: train_loss: 0.3395, train_accuracy: 83.1500, val_loss: 0.4872, val_accuracy: 73.4000
Epoch 14/25: train_loss: 0.3366, train_accuracy: 83.2833, val_loss: 0.5809, val_accuracy: 61.7000
Epoch 15/25: train_loss: 0.3277, train_accuracy: 83.9778, val_loss: 0.5424, val_accuracy: 72.7000
Epoch 16/25: train_loss: 0.3168, train_accuracy: 84.5889, val_loss: 0.4868, val_accuracy: 75.5000
Epoch 17/25: train_loss: 0.3136, train_accuracy: 84.6778, val_loss: 0.4832, val_accuracy: 74.3000
Epoch 18/25: train_loss: 0.3108, train_accuracy: 85.0611, val_loss: 0.4510, val_accuracy: 77.8000
Epoch 19/25: train_loss: 0.3019, train_accuracy: 85.5889, val_loss: 0.5142, val_accuracy: 72.2000
Epoch 20/25: train_loss: 0.2958, train_accuracy: 85.6611, val_loss: 0.4542, val_accuracy: 77.5000
Epoch 21/25: train_loss: 0.2899, train_accuracy: 86.2722, val_loss: 0.5203, val_accuracy: 73.0000
Epoch 22/25: train_loss: 0.2891, train_accuracy: 85.9778, val_loss: 0.4847, val_accuracy: 75.6000
Epoch 23/25: train_loss: 0.2846, train_accuracy: 86.7222, val_loss: 0.4609, val_accuracy: 76.1000
Epoch 24/25: train_loss: 0.2781, train_accuracy: 86.9556, val_loss: 0.4319, val_accuracy: 79.3000
Epoch 25/25: train_loss: 0.2721, train_accuracy: 87.1611, val_loss: 0.6320, val_accuracy: 72.6000
Traceback (most recent call last):
  File "ATML/main.py", line 114, in <module>
    torch.save(model.state_dict(), model_dir + 'model' + experiment_name + '.pt')
  File "/home/ubelix/artorg/kc12n043/miniconda3/envs/atml/lib/python3.7/site-packages/torch/serialization.py", line 224, in save
    return _with_file_like(f, "wb", lambda f: _save(obj, f, pickle_module, pickle_protocol))
  File "/home/ubelix/artorg/kc12n043/miniconda3/envs/atml/lib/python3.7/site-packages/torch/serialization.py", line 147, in _with_file_like
    f = open(f, mode)
FileNotFoundError: [Errno 2] No such file or directory: '../models/model7.pt'
